<?xml version="1.0"?>
<sdf version="1.5">
	<model name="iflight">
		<link name="body">
			<inertial>
                <pose>0 0 0 0 0 0</pose>
				<mass>0.392</mass>
				<inertia>
					<ixx>0.0003985</ixx>
                    <ixy>0.0</ixy>
                    <ixz>0.0</ixz>
					<iyy>0.0003985</iyy>
					<iyz>0.0</iyz>
                    <izz>0.0007905</izz>
				</inertia>
			</inertial>
			<collision name="collision">
				<geometry>
					<box>
						<size>0.11 0.11 0.01</size>
					</box>
				</geometry>
			</collision>
			<visual name="body_visual">
				<geometry>
					<box>
						<size>0.11 0.11 0.01</size>
					</box>
				</geometry>
				<material>
					<ambient>0.5 0.5 0.6 1</ambient>
					<diffuse>0.5 0.5 0.6 1</diffuse>
					<specular>0 0 0 1</specular>
					<emissive>0 0 0 1</emissive>
				</material>
			</visual>
		</link>

        <link name="rotor_0_base">
			<pose>0 0 0.0075 0 0 0</pose>
			<inertial>
				<pose>0 0 0 0 0 0</pose>
				<inertia>
                    <ixx>1.393E-9</ixx>
                    <ixy>0.0</ixy>
                    <ixz>0.0</ixz>
                    <iyy>1.393E-9</iyy>
                    <iyz>0.0</iyz>
                    <izz>9.766E-10</izz>
                </inertia>
                <mass>0.0003125</mass>
			</inertial>
			<collision name="rotor_0_base_collision">
				<geometry>
					<cylinder><radius>0.0025</radius><length>0.005</length></cylinder>
				</geometry>
			</collision>
			<visual name="rotor_0_base_visual">
				<geometry>
					<cylinder><radius>0.0025</radius><length>0.005</length></cylinder>
				</geometry>
				<material><ambient>0.8 0.3 0.3 0.5</ambient><diffuse>0.8 0.3 0.3 0.5</diffuse></material>
			</visual>
		</link>

        <link name="rotor_0_blade_0">
			<pose>0 0 0.01 0 0 0</pose>
			<inertial>
				<pose>0.0 0.0175 0 0.0 0.0 0.0</pose>
                <inertia>
                    <ixx>3.193E-8</ixx>
                    <ixy>0.0</ixy>
                    <ixz>0.0</ixz>
                    <iyy>2.63E-9</iyy>
                    <iyz>0.0</iyz>
                    <izz>3.4505E-8</izz>
                </inertia>
				<mass>0.0003125</mass>
			</inertial>
			<collision name="rotor_0_blade_0_collision">
				<pose>0 0.0175 0 0 0 0</pose>
				<geometry>
					<box><size>0.01 0.035 0.001</size></box>
				</geometry>
			</collision>
			<visual name="rotor_0_blade_0_visual">
				<pose>0 0.0175 0 0 0 0</pose>
				<geometry>
					<box><size>0.01 0.035 0.001</size></box>
				</geometry>
				<material><ambient>0.8 0.3 0.3 0.5</ambient><diffuse>0.8 0.3 0.3 0.5</diffuse></material>
			</visual>
		</link>

        <link name="rotor_0_blade_1">
			<pose>0 0 0.01 0 0 3.141593</pose>
			<inertial>
				<pose>0.0 0.0175 0 0.0 0.0 0.0</pose>
                <inertia>
                    <ixx>3.193E-8</ixx>
                    <ixy>0.0</ixy>
                    <ixz>0.0</ixz>
                    <iyy>2.63E-9</iyy>
                    <iyz>0.0</iyz>
                    <izz>3.4505E-8</izz>
                </inertia>
				<mass>0.0003125</mass>
			</inertial>
			<collision name="rotor_0_blade_1_collision">
				<pose>0 0.0175 0 0 0 0</pose>
				<geometry>
					<box><size>0.01 0.035 0.001</size></box>
				</geometry>
			</collision>
			<visual name="rotor_0_blade_1_visual">
				<pose>0 0.0175 0 0 0 0</pose>
				<geometry>
					<box><size>0.01 0.035 0.001</size></box>
				</geometry>
				<material><ambient>0.8 0.3 0.3 0.5</ambient><diffuse>0.8 0.3 0.3 0.5</diffuse></material>
			</visual>
		</link>


		<joint name="rotor_0_base_joint" type="revolute">
			<parent>body</parent>
			<child>rotor_0_base</child>
			<pose>0.0 0.0 0.0 0.0 0.0 0.0</pose>
			<axis>
			<limit>
				<lower>-1e16</lower>
				<upper>1e16</upper>
			</limit>
			<xyz>0.0 0.0 -1.0</xyz>
			<dynamics>
				<damping>0.0001</damping>
			</dynamics>
			</axis>
			<physics>
				<ode>
				<cfm_damping>1</cfm_damping>
				</ode>
			</physics>
		</joint>
        <joint name="rotor_0_blade_0_joint" type="fixed">
			<parent>rotor_0_base</parent>
			<child>rotor_0_blade_0</child>
			<pose>0 0 0 0 0 0</pose>
		</joint>
        <joint name="rotor_0_blade_1_joint" type="fixed">
			<parent>rotor_0_base</parent>
			<child>rotor_0_blade_1</child>
			<pose>0 0 0 0 0 0</pose>
		</joint>

		<plugin filename="gz-sim-joint-state-publisher-system"
        name="gz::sim::systems::JointStatePublisher">
		</plugin>
    
		<plugin
        filename="gz-sim-apply-joint-force-system"
        name="gz::sim::systems::ApplyJointForce">
        	<joint_name>rotor_0_base_joint</joint_name>
      	</plugin>

        <plugin
			filename="gz-sim-lift-drag-system"
			name="gz::sim::systems::LiftDrag">
			<a0>0.1</a0>
			<cla>0.1</cla>
			<cda>0.001</cda>
			<cma>0.0</cma>
			<cp>0.0 0.0175 0</cp>
			<area>0.00035</area>
			<air_density>1.2041</air_density>
			<forward>1 0 0</forward>
			<upward>0 0 1</upward>
			<link_name>rotor_0_blade_0</link_name>
		</plugin>

        <plugin
			filename="gz-sim-lift-drag-system"
			name="gz::sim::systems::LiftDrag">
			<a0>0.1</a0>
			<cla>0.1</cla>
			<cda>0.001</cda>
			<cma>0.0</cma>
			<cp>0.0 0.0175 0</cp>
			<area>0.00035</area>
			<air_density>1.2041</air_density>
			<forward>1 0 0</forward>
			<upward>0 0 1</upward>
			<link_name>rotor_0_blade_1</link_name>
		</plugin>
	</model>
</sdf>
